Workbook
Name AppCustomization: 'Effort Estimation'!$C$70
Name AppFeatures: 'Effort Estimation'!$C$53
Name Automations: 'Effort Estimation'!$C$106
Name Build_and_Configure: 'Effort Estimation'!$C$35
Name Calculations: 'Effort Estimation'!$C$74
Name Change_Management: 'Effort Estimation'!$C$128
Name Design: 'Effort Estimation'!$C$28
Name Documentations: 'Effort Estimation'!$C$123
Name DynamicList: IF('Scope Definition'!$C$7="YES", [0]!Yes_List, [0]!No_List)
Name DynamicList: IF('Scope Definition'!$C$7="YES", Yes_List, No_List)
Name EngagementWeightage: 'Scope Definition'!$E$103
Name FeatureCleanRange: 'Scope Definition'!$G$6:$G$102
Name FTEEfforts: 'App Tiers Definition'!$H$5:$V$22
Name HistData: 'Effort Estimation'!$C$84
Name InScopeFlagRange: 'Scope Definition'!$H$6:$H$102
Name Integrations: 'Effort Estimation'!$C$90
Name KDD_Items: Definitions!$D$134:$D$149
Name KDD_Items_All: Definitions!$B$134:$B$149
Name No_List: 'Scope Definition'!$Z$5
Name Project_Initiation_and_Planning: 'Effort Estimation'!$C$5
Name Reporting: 'Effort Estimation'!$C$97
Name Requirement_Gathering: 'Effort Estimation'!$C$18
Name RoleData: 'Scope Definition'!$K$14:$L$26
Name RoleTable: 'Scope Definition'!$K$14:$L$26
Name Scope_of_Services: Definitions!$B$3:$B$62
Name Security: 'Effort Estimation'!$C$80
Name Testing_Training: 'Effort Estimation'!$C$112
Name TierTable: 'App Tiers Definition'!$D$6:$F$10
Name Timings: Definitions!$B$166:$O$191
Name TotalDuration: 'Effort Estimation'!$H$132
Name Transition: 'Effort Estimation'!$C$119
Name Weightage: 'Scope Definition'!$E$103
Name Yes_List: 'Scope Definition'!$Y$5:$Y$9

Sheet Scope Definition
B3: FCC Implementation Scope | C3: In Scope? | D3: Details | G3: Feature Clean | H3: In Scope Flag
Y4: Yes_List | Z4: No_List
B5: Dimensions | X5: YES | Y5: 1 | Z5: 0
B6: Account | C6: YES | D6: 2000 | E6: =1 + IF(C7="NO", 0, IF(AND(D7>0, D7<=2), 1, IF(AND(D7>2,D7<=4), 2, IF(AND(D7>4,D7<=6), 3, IF(AND(D7>6,D7<=8), 4, ""))))) + IF(C8="YES",2,0) -> 4 | G6: =TRIM(B6) -> Account | H6: =IF(C6="YES",1,0) -> 1 | X6: NO | Y6: 2
B7: Account Alternate Hierarchies | C7: YES | D7: 2 | G7: =TRIM(B7) -> Account Alternate Hierarchies | H7: =IF(C7="YES",1,0) -> 1 | Y7: 3
B8: Rationalization of CoA | C8: YES | D8: 3 | G8: =TRIM(B8) -> Rationalization of CoA | H8: =IF(C8="YES",1,0) -> 1
B9: Multi-Currency | C9: YES | D9: 5 | E9: =IF(C9="NO", 0, IF(AND(D9>0, D9<=5), 1, IF(AND(D9>5,D9<=10), 2, IF(AND(D9>10,D9<=15), 3, IF(AND(D9>15,D9<=20), 4, 8))))) -> 1 | G9: =TRIM(B9) -> Multi-Currency | H9: =IF(C9="YES",1,0) -> 1 | Y9: 4
B10: Reporting Currency | C10: YES | D10: 2 | E10: =IF(D10=1,0,IF(AND(D10>1,D10<=2),2,IF(AND(D10>2,D10<=4),3,5))) -> 2 | G10: =TRIM(B10) -> Reporting Currency | H10: =IF(C10="YES",1,0) -> 1
B11: Entity | C11: YES | D11: 25 | E11: =1 + IF(C11="YES",2,0)+ IF(C13="NO", 0, IF(AND(D13>0, D13<=2), 1, IF(AND(D13>2,D13<=4), 2, IF(AND(D13>4,D13<=6), 3, IF(AND(D13>6,D13<=8), 4, 5))))) -> 4 | G11: =TRIM(B11) -> Entity | H11: =IF(C11="YES",1,0) -> 1
B12: Entity Redesign | C12: NO | G12: =TRIM(B12) -> Entity Redesign | H12: =IF(C12="YES",1,0) -> 0
B13: Entity Alternate Hierarchies | C13: YES | D13: 2 | G13: =TRIM(B13) -> Entity Alternate Hierarchies | H13: =IF(C13="YES",1,0) -> 1 | K13: Select the necessary roles for this engagement
B14: Scenario | C14: YES | D14: 2 | E14: =IF(D14=1,1,IF(AND(D14>1,D14<=2),3,IF(AND(D14>2,D14<=3),4,IF(AND(D14>3,D14<=4),5,6)))) -> 3 | G14: =TRIM(B14) -> Scenario | H14: =IF(C14="YES",1,0) -> 1 | K14: PM USA | L14: TRUE
B15: Multi-GAAP | C15: YES | E15: =IF(C15="NO", 0, 1) -> 1 | G15: =TRIM(B15) -> Multi-GAAP | H15: =IF(C15="YES",1,0) -> 1 | K15: PM India | L15: TRUE
B16: Custom Dimensions | C16: YES | D16: 2 | E16: =IF(C16="NO", 0, IF(AND(D16>0, D16<=2), 1, IF(AND(D16>2,D16<=3), 2, IF(AND(D16>10,D16<=15), 3, IF(AND(D16>15,D16<=20), 4, ""))))) + IF(C17="NO", 0, IF(AND(D17>0, D17<=5), 1, IF(AND(D17>5,D17<=10), 2, IF(AND(D17>10,D17<=15), 3, IF(AND(D17>15,D17<=20), 4, ""))))) -> 2 | G16: =TRIM(B16) -> Custom Dimensions | H16: =IF(C16="YES",1,0) -> 1 | K16: Architect USA | L16: TRUE
B17: Alternate Hierarchies in Custom Dimensions | C17: YES | D17: 2 | G17: =TRIM(B17) -> Alternate Hierarchies in Custom Dimensions | H17: =IF(C17="YES",1,0) -> 1 | K17: Delivery Lead India | L17: TRUE
B18: Additional Alias Tables | C18: YES | D18: 1 | E18: =IF(C18="NO", 0, IF(AND(D18>0, D18<=5), 1, IF(AND(D18>5,D18<=10), 2, IF(AND(D18>10,D18<=15), 3, IF(AND(D18>15,D18<=20), 4, ""))))) -> 1 | G18: =TRIM(B18) -> Additional Alias Tables | H18: =IF(C18="YES",1,0) -> 1 | K18: Sr. Delivery Lead India | L18: TRUE
G19: =TRIM(B19) | H19: =IF(C19="YES",1,0) -> 0 | K19: App Lead USA | L19: TRUE
B20: Application Features | G20: =TRIM(B20) -> Application Features | H20: =IF(C20="YES",1,0) -> 0 | K20: App Lead India | L20: TRUE
B21: Elimination | C21: YES | E21: =IF(C21="YES",1,0) -> 1 | G21: =TRIM(B21) -> Elimination | H21: =IF(C21="YES",1,0) -> 1 | K21: App Developer USA | L21: FALSE
B22: Custom Elimination Requirement | C22: NO | G22: =TRIM(B22) -> Custom Elimination Requirement | H22: =IF(C22="YES",1,0) -> 0 | K22: App Developer India | L22: TRUE
B23: Consolidation Journals | C23: YES | E23: =IF(C23="YES",1,0) + IF(C24="NO",0,IF(AND(D24>0,D24<=2),1,IF(AND(D24>2,D24<=5),2,4))) + IF(C25="NO",0,2) -> 4 | G23: =TRIM(B23) -> Consolidation Journals | H23: =IF(C23="YES",1,0) -> 1 | K23: Integration Lead USA | L23: TRUE
B24: Journal Templates | C24: YES | D24: 1 | G24: =TRIM(B24) -> Journal Templates | H24: =IF(C24="YES",1,0) -> 1 | K24: Integration Developer India | L24: TRUE
B25: Parent Currency Journals | C25: YES | G25: =TRIM(B25) -> Parent Currency Journals | H25: =IF(C25="YES",1,0) -> 1 | K25: Reporting Lead India | L25: FALSE
B26: Ownership Management | C26: NO | E26: =IF(C26="YES",2,0) + IF(C26="YES",IF(C27="YES",2,0),0)+ IF(C26="YES",IF(C28="YES",2,0),0) + IF(C26="YES",IF(C29="YES",2,0),0) + IF(C26="YES",IF(C30="YES",2,0),0) -> 0 | G26: =TRIM(B26) -> Ownership Management | H26: =IF(C26="YES",1,0) -> 0 | K26: Security Lead India | L26: FALSE
B27: Enhanced Organization by Period | C27: NO | G27: =TRIM(B27) -> Enhanced Organization by Period | H27: =IF(C27="YES",1,0) -> 0
B28: Equity Pickup | C28: NO | G28: =TRIM(B28) -> Equity Pickup | H28: =IF(C28="YES",1,0) -> 0
B29: Partner Elimination | C29: NO | G29: =TRIM(B29) -> Partner Elimination | H29: =IF(C29="YES",1,0) -> 0
B30: Configurable Consolidation Rules | C30: NO | G30: =TRIM(B30) -> Configurable Consolidation Rules | H30: =IF(C30="YES",1,0) -> 0
B31: Cash Flow | C31: YES | E31: =IF(C31="YES",2,0) -> 2 | G31: =TRIM(B31) -> Cash Flow | H31: =IF(C31="YES",1,0) -> 1
B32: Supplemental Data Collection | C32: NO | E32: =IF(C32="YES",2,0) -> 0 | G32: =TRIM(B32) -> Supplemental Data Collection | H32: =IF(C32="YES",1,0) -> 0
B33: Enterprise Journals | C33: NO | E33: =IF(C33="YES",2,0) -> 0 | G33: =TRIM(B33) -> Enterprise Journals | H33: =IF(C33="YES",1,0) -> 0
B34: Approval Process | C34: YES | E34: =IF(C34="YES",2,0) -> 2 | G34: =TRIM(B34) -> Approval Process | H34: =IF(C34="YES",1,0) -> 1
B35: Historic Overrides | C35: YES | E35: =IF(C35="YES",2,0)+IF(D10=1,0,IF(AND(D10>1,D10<=2),2,5)) -> 4 | G35: =TRIM(B35) -> Historic Overrides | H35: =IF(C35="YES",1,0) -> 1
B36: Task Manager | C36: NO | E36: =IF(C36="YES",2,0) -> 0 | G36: =TRIM(B36) -> Task Manager | H36: =IF(C36="YES",1,0) -> 0
B37: Audit | C37: YES | E37: =IF(C37="YES",1,0) -> 1 | G37: =TRIM(B37) -> Audit | H37: =IF(C37="YES",1,0) -> 1
G38: =TRIM(B38) | H38: =IF(C38="YES",1,0) -> 0
B39: Application Customization | G39: =TRIM(B39) -> Application Customization | H39: =IF(C39="YES",1,0) -> 0
B40: Data Forms | C40: YES | D40: 5 | E40: {=IF(C40="YES",1,0)+IF(C40="YES", _xlfn.IFS( D40="", 0, D40=1, 2, D40<=4, 5, D40<=10, 10, D40<=15, 20, D40<=25, 30, D40<=35, 40, TRUE, 50 ), 0 )} -> 11 | G40: =TRIM(B40) -> Data Forms | H40: =IF(C40="YES",1,0) -> 1
B41: Dashboards | C41: NO | D41: 3 | E41: {=IF(C41="YES",1,0)+IF(C41="YES", _xlfn.IFS( D41="", 0, D41=1, 4, D41<=2, 8, D41<=4, 10, TRUE, 25 ), 0 )} -> 0 | G41: =TRIM(B41) -> Dashboards | H41: =IF(C41="YES",1,0) -> 0
G42: =TRIM(B42) | H42: =IF(C42="YES",1,0) -> 0
...

Sheet Scope of Service
C2: Tier 3 - Enhanced Scope
C4: Scope of Services
C6: Under this SOW, Donyati will work with Client to provide Services noted below. Actual activities, work items, schedule and deliverables would be jointly managed by Donyati and Client based on the Client’s business priorities.
C8: The scope of this engagement is focused on the implementation of the following application modules:
C9: Oracle EPM Enterprise – Financial Consolidation and Close
C11: Donyati Services consist of the following:
C13: Implementation of Financial Consolidation and Close
C15: Dimensions
C16: Account dimension (~ 2000accounts) will be configured based on the current Chart of Accounts. CoA Rationalization will be performed. Standard Trial Balance will be incorporated into the Account dimension to support the following financial statements.
C17: Up to 2 Account alternate hierarchies will be developed
C18: Entity - (~25) will be configures based on the currenct structure. In addtion, up to 2 alternate hierarchies will be developed
C19: Currency dimension will be configures with 5 Currencies.There will be 2 Reporting Currency
... C46: Translation override will be set up if required

Sheet Timings
C4: Timings
C6: The engagement start date is 13-Aug-2025
C7: The engagement end date is 30-Apr-2026
C8: Go-live support will be provided and additional capabilities will be added per a subsequent Statement of Work expected to be started immediately following the completion of this Statement of Work.
C9: This SOW assumes 8 months to complete Financial Consolidation and Close.
C10: Completion of Services and Deliverables agreed upon is subject to, among other things, appropriate cooperation, obtaining the necessary information, and timely response to inquiries. The chart below shows the estimated hours per month for each resource role. At the conclusion of Requirements and Design, Donyati will revise the implementation timeline to incorporate agreed upon requirements and design elements. Donyati and Client will review and approve the revised implementation timeline before moving into the Development Phase.
C14: Resource Role/Monthly Hours | D14: 1 | E14: 2 | F14: 3 | G14: 4 | H14: 5 | I14: 6 | J14: 7 | K14: 8
C15: PM USA | D15: 118 | E15: 118 | F15: 118 | G15: 118 | H15: 118 | I15: 118 | J15: 118 | K15: 118
C16: PM India | D16: 118 | E16: 118 | F16: 118 | G16: 118 | H16: 118 | I16: 118 | J16: 118 | K16: 118
C17: Architect USA | D17: 58 | E17: 58 | F17: 58 | G17: 58 | H17: 58 | I17: 58 | J17: 58 | K17: 58
C18: Sr. Delivery Lead India | D18: 118 | E18: 118 | F18: 118 | G18: 118 | H18: 118 | I18: 118 | J18: 118 | K18: 118
C19: Delivery Lead India | D19: 118 | E19: 118 | F19: 118 | G19: 118 | H19: 118 | I19: 118 | J19: 118 | K19: 118
C20: App Lead USA | D20: 234 | E20: 234 | F20: 234 | G20: 234 | H20: 234 | I20: 234 | J20: 234 | K20: 234
C21: App Lead India | D21: 234 | E21: 234 | F21: 234 | G21: 234 | H21: 234 | I21: 234 | J21: 234 | K21: 234
C22: App Developer India | D22: 223 | E22: 223 | F22: 223 | G22: 223 | H22: 223 | I22: 223 | J22: 223 | K22: 223
C23: Integration Lead USA | D23: 55 | E23: 55 | F23: 55 | G23: 55 | H23: 55 | I23: 55 | J23: 55 | K23: 55
C24: Integration Developer India | D24: 55 | E24: 55 | F24: 55 | G24: 55 | H24: 55 | I24: 55 | J24: 55 | K24: 55

Sheet KDD Items
C4: KDD Items
C6: KDD01 - General Application Configuration
C7: KDD02 - Metadata Configuration
C8: KDD03 - FCC Consolidations and Other Calculations
C9: KDD04 - Reports and Data Form Configuration
C10: KDD05 - Cash Flow
C11: KDD06 - Journal Process
C12: KDD07 - Integrations
C13: KDD08 - Historical Data Source and Validations
C14: KDD09 - Automations
C15: KDD10 - Approval Process
C16: KDD11 - Application Security
C17: KDD12 - Audit

Sheet App Tiers Definition
J3: % of FTE Efforts
E4: Weightage | J4: USA | K4: India | L4: USA | M4: India | N4: India | O4: USA | P4: India | Q4: USA | R4: India | S4: USA | T4: India | U4: India | V4: India
E5: Range | I5: Hours | J5: PM | K5: PM | L5: Architect | M5: Sr. Delivery Lead | N5: Delivery Lead | O5: App Lead | P5: App Lead | Q5: App Developer | R5: App Developer | S5: Integration Lead | T5: Integration Developer | U5: Reporting Lead | V5: Security Lead
D6: Tier 1 - Jumpstart | E6: 0 | F6: 60 | H6: Project Initiation and Planning | I6: ='Effort Estimation'!G5 -> 18 | J6: 0.5 | K6: 0.5 | L6: 1 | M6: 0.5 | N6: 0.5 | O6: 0 | P6: 0 | Q6: 0 | R6: 0 | S6: 0 | T6: 0 | U6: 0 | V6: 0 | AA6: TECO | AB6: 52
D7: Tier 2 - Foundation Plus | E7: 61 | F7: 100 | H7: Creating and Managing EPM Cloud Infrastructure | I7: ='Effort Estimation'!G14 -> 6 | J7: 0.5 | K7: 0.5 | L7: 0 | M7: 0.5 | N7: 0.5 | O7: 1 | P7: 1 | Q7: 0 | R7: 0 | S7: 0 | T7: 0 | U7: 0 | V7: 0 | AA7: Summit Polymers
D8: Tier 3 - Enhanced Scope | E8: 101 | F8: 150 | H8: Requirement Gathering, Read back and Client Sign-off | I8: ='Effort Estimation'!G18 -> 44 | J8: 0.5 | K8: 0.5 | L8: 1 | M8: 0.5 | N8: 0.5 | O8: 1 | P8: 1 | Q8: 0 | R8: 0 | S8: 0.2 | T8: 0.2 | U8: 0 | V8: 0 | AA8: Labrie
D9: Tier 4 - Advanced Enablement | E9: 151 | F9: 200 | H9: Design | I9: ='Effort Estimation'!G28 -> 42 | J9: 0.5 | K9: 0.5 | L9: 1 | M9: 0.5 | N9: 0.5 | O9: 1 | P9: 1 | Q9: 0 | R9: 0 | S9: 0.2 | T9: 0.2 | U9: 0 | V9: 0 | AA9: Jtekt | AB9: 100
D10: Tier 5 - Full Spectrum | E10: 201 | F10: 999 | H10: Build and Configure FCC | I10: ='Effort Estimation'!G35 -> 148 | J10: 0.5 | K10: 0.5 | L10: 0.2 | M10: 0.5 | N10: 0.5 | O10: 1 | P10: 1 | Q10: 1 | R10: 1 | S10: 0 | T10: 0 | U10: 0 | V10: 0 | AA10: Delta
H11: Setup Application Features | I11: ='Effort Estimation'!G53 -> 96.5 | J11: 0.5 | K11: 0.5 | L11: 0.2 | M11: 0.5 | N11: 0.5 | O11: 1 | P11: 1 | Q11: 1 | R11: 1 | S11: 0 | T11: 0 | U11: 0 | V11: 0 | AA11: Cooper Std | AB11: 133
H12: Application Customization | I12: ='Effort Estimation'!G70 -> 72 | J12: 0.5 | K12: 0.5 | L12: 0.2 | M12: 0.5 | N12: 0.5 | O12: 1 | P12: 1 | Q12: 1 | R12: 1 | S12: 0 | T12: 0 | U12: 0 | V12: 0 | AA12: Central Ins
H13: Calculations | I13: ='Effort Estimation'!G74 -> 126 | J13: 0.5 | K13: 0.5 | L13: 0.2 | M13: 0.5 | N13: 0.5 | O13: 1 | P13: 1 | Q13: 1 | R13: 1 | S13: 0 | T13: 0 | U13: 0 | V13: 0 | AA13: MTW
H14: Security | I14: ='Effort Estimation'!G80 -> 24 | J14: 0.5 | K14: 0.5 | L14: 0.2 | M14: 0.5 | N14: 0.5 | O14: 1 | P14: 1 | Q14: 1 | R14: 1 | S14: 0.2 | T14: 0.2 | U14: 0 | V14: 1
H15: Historical Data | I15: ='Effort Estimation'!G84 -> 552 | J15: 0.5 | K15: 0.5 | L15: 0.2 | M15: 0.5 | N15: 0.5 | O15: 1 | P15: 1 | Q15: 1 | R15: 1 | S15: 0 | T15: 0 | U15: 0 | V15: 0
H16: Integrations | I16: ='Effort Estimation'!G90 -> 140 | J16: 0.5 | K16: 0.5 | L16: 0.2 | M16: 0.5 | N16: 0.5 | O16: 1 | P16: 1 | Q16: 1 | R16: 1 | S16: 1 | T16: 1 | U16: 0 | V16: 0
H17: Reporting | I17: ='Effort Estimation'!G97 -> 140 | J17: 0.5 | K17: 0.5 | L17: 0.2 | M17: 0.5 | N17: 0.5 | O17: 1 | P17: 1 | Q17: 1 | R17: 1 | S17: 0 | T17: 0 | U17: 1 | V17: 0
H18: Automations | I18: ='Effort Estimation'!G106 -> 64 | J18: 0.5 | K18: 0.5 | L18: 0.2 | M18: 0.5 | N18: 0.5 | O18: 1 | P18: 1 | Q18: 1 | R18: 1 | S18: 1 | T18: 1 | U18: 0 | V18: 0
H19: Testing/Training | I19: ='Effort Estimation'!G112 -> 244 | J19: 0.5 | K19: 0.5 | L19: 0.2 | M19: 0.5 | N19: 0.5 | O19: 1 | P19: 1 | Q19: 1 | R19: 1 | S19: 0.5 | T19: 0.5 | U19: 0.2 | V19: 0
H20: Transition | I20: ='Effort Estimation'!G119 -> 96 | J20: 0.5 | K20: 0.5 | L20: 0.2 | M20: 0.5 | N20: 0.5 | O20: 1 | P20: 1 | Q20: 1 | R20: 1 | S20: 0.5 | T20: 0.5 | U20: 0 | V20: 0
H21: Documentations | I21: ='Effort Estimation'!G123 -> 36 | J21: 0.5 | K21: 0.5 | L21: 0.2 | M21: 0.5 | N21: 0.5 | O21: 1 | P21: 1 | Q21: 1 | R21: 1 | S21: 0.5 | T21: 0.5 | U21: 0 | V21: 0
H22: Change Management | I22: ='Effort Estimation'!G128 -> 44 | J22: 0.5 | K22: 0.5 | L22: 0.2 | M22: 0.5 | N22: 0.5 | O22: 1 | P22: 1 | Q22: 1 | R22: 1 | S22: 0.5 | T22: 0.5 | U22: 0 | V22: 0
I24: =SUM(I6:I22) -> 1892.5 | J24: =SUMPRODUCT($I6:$I22,J6:J22) -> 946.25 | K24: =SUMPRODUCT($I6:$I22,K6:K22) -> 946.25 | L24: =SUMPRODUCT($I6:$I22,L6:L22) -> 460.5 | M24: =SUMPRODUCT($I6:$I22,M6:M22) -> 946.25 | N24: =SUMPRODUCT($I6:$I22,N6:N22) -> 946.25 | O24: =SUMPRODUCT($I6:$I22,O6:O22) -> 1874.5 | P24: =SUMPRODUCT($I6:$I22,P6:P22) -> 1874.5 | Q24: =SUMPRODUCT($I6:$I22,Q6:Q22) -> 1782.5 | ... V24: =SUMPRODUCT($I6:$I22,V6:V22) -> 24

Sheet Effort Estimation
B3: FCC Tasks | C3: Time in hours | D3: In Scope? | E3: Details | F3: Total Time | G3: Final Estimate | H3: in Days
B5: Project Initiation and Planning | C5: =SUM(C6:C12) -> 12 | F5: =IF(EngagementWeightage<=100, Project_Initiation_and_Planning,IF(EngagementWeightage<=120,Project_Initiation_and_Planning+4,IF(EngagementWeightage<=160, Project_Initiation_and_Planning+6,Project_Initiation_and_Planning+8))) -> 18 | G5: =SUM(F5:F12) -> 18 | H5: =G5/8 -> 2.25
B6: Kickoff Meetings | C6: 1 | D6: YES
B7: Project Governance | C7: 1 | D7: YES
B8: Communication Plan | C8: 1 | D8: YES
B9: Resource Allocation | C9: 2 | D9: YES
B10: RAID Log | C10: 1 | D10: YES
B11: Project Plan | C11: 4 | D11: YES
B12: Plan Status Meetings and SteerCo Meeting Schedule | C12: 2 | D12: YES
B14: Creating and Managing EPM Cloud Infrastructure | C14: =SUM(C15:C16) -> 6 | F14: =C14 -> 6 | G14: =SUM(F14:F16) -> 6 | H14: =G14/8 -> 0.75
B15: Creating and Setting up Oracle EPM Cloud instances | C15: 2 | D15: YES
B16: Prelim FCC User Provisioning | C16: 4 | D16: =IF(_xlfn.XLOOKUP("Number of Users", FeatureCleanRange, [0]!InScopeFlagRange, 0)=1, "YES", "NO") -> YES | E16: =IF(D16="YES",'Scope Definition'!D51,0) -> 20 | F16: =IF(E16>50,8,0) -> 0
B18: Requirement Gathering, Read back and Client Sign-off | C18: =SUM(C19:C26) -> 32 | F18: =IF(EngagementWeightage<=100, Requirement_Gathering,IF(EngagementWeightage<=120,Requirement_Gathering+8,IF(EngagementWeightage<=160, Requirement_Gathering+12,Requirement_Gathering+16))) -> 44 | G18: =SUM(F18) -> 44 | H18: =G18/8 -> 5.5
B19: Requirement Gathering Sessions | C19: 8 | D19: YES
B20: Current CoA details | C20: 4 | D20: YES
B21: CoA Hierarchies | C21: 4 | D21: YES
B22: Current Consolidation Model | C22: 4 | D22: YES
B23: Sample Reports | C23: 2 | D23: YES
B24: Dimension Details | C24: 4 | D24: YES
B25: Develop Requirement Treaceability Matrix | C25: 4 | D25: YES
B26: Formal RTM Signoff | C26: 2 | D26: YES
B28: Design | C28: =SUM(C29:C33) -> 26 | F28: =IF(EngagementWeightage<=100, Design,IF(EngagementWeightage<=120,Design+8,IF(EngagementWeightage<=160, Design+16,Design+24))) -> 42 | G28: =SUM(F28:F33) -> 42 | H28: =G28/8 -> 5.25
B29: Design Document | C29: 8 | D29: YES
B30: Key Design Decision Document | C30: 8 | D30: YES
B31: Internal Peer Review | C31: 4 | D31: YES
B32: Design and KDD Reviews | C32: 4 | D32: YES
B33: Design Approval from Client | C33: 2 | D33: YES
B35: Build and Configure FCC | C35: =SUM(C36:C51) -> 88 | F35: =IF(EngagementWeightage<=100, Build_and_Configure,IF(EngagementWeightage<=120,Build_and_Configure+8,IF(EngagementWeightage<=160, Build_and_Configure+16,Build_and_Configure+24))) -> 104 | G35: =SUM(F35:F51) -> 148 | H35: =G35/8 -> 18.5
B36: Application Configuration | C36: 2 | D36: YES
B37: Account | C37: 16 | D37: =IF(_xlfn.XLOOKUP(B37, FeatureCleanRange, [0]!InScopeFlagRange, 0)=1, "YES", "NO") -> YES
B38: Account Alternate Hierarchies | C38: 8 | D38: =IF(_xlfn.XLOOKUP(B38, FeatureCleanRange, [0]!InScopeFlagRange, 0)=1, "YES", "NO") -> YES | E38: =IF(D38="YES",'Scope Definition'!D7,0) -> 2 | F38: =C38*E38 -> 16
B39: Rationalization of CoA | C39: 24 | D39: =IF(_xlfn.XLOOKUP(B39, FeatureCleanRange, [0]!InScopeFlagRange, 0)=1, "YES", "NO") -> YES
B40: Multi Currency | C40: 1 | D40: =IF(_xlfn.XLOOKUP(B40, FeatureCleanRange, [0]!InScopeFlagRange, 0)=1, "YES", "NO") -> NO | E40: =IF(D40="YES",'Scope Definition'!D9,0) -> 0 | F40: =C40*E40 -> 0
B41: Reporting Currency | C41: 0.5 | D41: =IF(_xlfn.XLOOKUP(B41, FeatureCleanRange, [0]!InScopeFlagRange, 0)=1, "YES", "NO") -> YES | E41: =IF(D41="YES",'Scope Definition'!D10,0) -> 2 | F41: =C41*E41 -> 1
B42: Data Source | C42: 0.5 | D42: YES
B43: Entity | C43: 8 | D43: =IF(_xlfn.XLOOKUP(B43, FeatureCleanRange, [0]!InScopeFlagRange, 0)=1, "YES", "NO") -> YES
B44: Entity Redesign | C44: 8 | D44: =IF(_xlfn.XLOOKUP(B44, FeatureCleanRange, [0]!InScopeFlagRange, 0)=1, "YES", "NO") -> NO
B45: Entity Alternate Hierarchies | C45: 4 | D45: =IF(_xlfn.XLOOKUP(B45, FeatureCleanRange, [0]!InScopeFlagRange, 0)=1, "YES", "NO") -> YES | E45: =IF(D45="YES",'Scope Definition'!D13,0) -> 2 | F45: =C45*E45 -> 8
B46: Movement | C46: 4 | D46: YES
B47: Scenario | C47: 1 | D47: =IF(_xlfn.XLOOKUP(B47, FeatureCleanRange, [0]!InScopeFlagRange, 0)=1, "YES", "NO") -> YES | E47: =IF(D47="YES",'Scope Definition'!D14,0) -> 2 | F47: =C47*E47 -> 2
...

Sheet Sheet1
D8: Resource Role / | E8: 1 | F8: 2 | G8: 3 | H8: 4 | I8: 5 | J8: 6 | K8: 7 | L8: 8 | M8: 9
D9: Monthly Hours
D10: Project Manager - USA (50%) | E10: 44 | F10: 88 | G10: 84 | H10: 84 | I10: 92 | J10: 72 | K10: 88 | L10: 108
D11: Project Manager - India (50%) | E11: 44 | F11: 88 | G11: 84 | H11: 84 | I11: 92 | J11: 72 | K11: 88 | L11: 108
D12: Solution Architect - FCC -– USA | E12: 88 | F12: 88 | G12: 34 | H12: 34 | I12: 37 | J12: 29 | K12: 35 | L12: 112
D13: Integration Architect -– USA | E13: 44 | F13: 88 | G13: 34 | H13: 34 | I13: 5
D14: Integration Lead -– India | F14: 176 | G14: 168 | H14: 168 | I14: 184 | J14: 144 | K14: 176 | L14: 168 | M14: 160
D15: Application Lead - FCC -– USA | F15: 176 | G15: 168 | H15: 168 | I15: 184 | J15: 144 | K15: 176 | L15: 168 | M15: 160
D16: Sr. Application Lead - FCC - India | F16: 176 | G16: 168 | H16: 168 | I16: 184 | J16: 144 | K16: 176 | L16: 144
D17: Application Lead - Reports - India | F17: 176 | G17: 168 | H17: 168 | I17: 184 | J17: 144 | K17: 176 | L17: 144
D18: Melissa - Change Management Supportgt | E18: 2 | F18: 2 | G18: 2 | H18: 2 | I18: 2 | J18: 2 | K18: 2 | L18: 6
K21: 7010

Sheet Definitions
B3: Scope of Services
B5: Under this SOW, Donyati will work with Client to provide Services noted below. Actual activities, work items, schedule and deliverables would be jointly managed by Donyati and Client based on the Client’s business priorities.
B7: The scope of this engagement is focused on the implementation of the following application modules:
B8: Oracle EPM Enterprise – Financial Consolidation and Close
B10: Donyati Services consist of the following:
B12: Implementation of Financial Consolidation and Close
B14: Dimensions
B15: ="Account dimension (~ "&'Scope Definition'!D6&"accounts) will be configured based on the current Chart of Accounts. " & IF('Scope Definition'!C8="NO","No redesign of the Chart of Accounts is anticipated in the SOW.","CoA Rationalization will be performed.") & " Standard Trial Balance will be incorporated into the Account dimension to support the following financial statements." -> Account dimension (~ 2000accounts) will be configured based on the current Chart of Accounts. CoA Rationalization will be performed. Standard Trial Balance will be incorporated into the Account dimension to support the following financial statements.
B16: ="Up to "&'Scope Definition'!D7&" Account alternate hierarchies will be developed" -> Up to 2 Account alternate hierarchies will be developed
B17: ="Entity - (~"&'Scope Definition'!D11&") will be configures based on the currenct structure. In addtion, up to "&'Scope Definition'!D13&" alternate hierarchies will be developed" -> Entity - (~25) will be configures based on the currenct structure. In addtion, up to 2 alternate hierarchies will be developed
B18: ="Currency dimension will be configures with "&'Scope Definition'!D9& " Currencies.There will be "&'Scope Definition'!D10& " Reporting Currency" -> Currency dimension will be configures with 5 Currencies.There will be 2 Reporting Currency
B19: =IF('Scope Definition'!C31="YES", "Movement dimension will be configured to support Cash Flow and Roll-forward activities.", "Movement dimension will be configured to support Roll-forward activities.") -> Movement dimension will be configured to support Cash Flow and Roll-forward activities.
B20: Year, Period, View, Consolidation, Intercompany, and Data Source dimensions will be configured to support consolidation and reporting
B21: ="Custom dimensions will be leveraged to support additional reporting requirements. Specific use of "&'Scope Definition'!D16&" Custom Dimensions will be determined during requirements and design" -> Custom dimensions will be leveraged to support additional reporting requirements. Specific use of 2 Custom Dimensions will be determined during requirements and design
B22: =IF('Scope Definition'!C17="NO", "Custom dimensions will have only one primary hierarchy", "Custom dimensions will have "&'Scope Definition'!D17& " alternate hierarchies") -> Custom dimensions will have 2 alternate hierarchies
B24: Application Features
B25: =IF('Scope Definition'!C21="YES","Standard elimination capabilities will be provided","Elimination is not in scope") -> Standard elimination capabilities will be provided
B26: =IF('Scope Definition'!C23="YES","Consolidation Journal will be enabled","Journals are not in scope") & " and " & IF('Scope Definition'!C24="YES",'Scope Definition'!D24& " Journal Template will be created", "Journal Templates are not in scope") -> Consolidation Journal will be enabled and 1 Journal Template will be created
B27: =IF('Scope Definition'!C26="NO","Ownership Management is not in scope, " & "No Equity pickup", "Ownership management will be enabled." ) -> Ownership Management is not in scope, No Equity pickup
B28: =IF('Scope Definition'!C29="YES","Partner Elimination will be enabled", " ")
B29: =IF('Scope Definition'!C30="YES","Configurable Consolidartion Rules will be used", " ")
B30: =IF('Scope Definition'!C31="YES","Our of box Configuration of indirect Cash Flow will be used.", "Cash Flow is not in scope.") -> Our of box Configuration of indirect Cash Flow will be used.
B31: =IF('Scope Definition'!C32="YES","Supplemental Data Collection will be enabled.", " ")
B32: =IF('Scope Definition'!C33="YES","Enterprise Journals will be enabled.", "")
B33: =IF('Scope Definition'!C34="YES","Approval Process will be used in the application.", "") -> Approval Process will be used in the application.
B34: =IF('Scope Definition'!C35="YES","Task Manager will be used in the application to support Financial Consolidation and Close.", "") -> Task Manager will be used in the application to support Financial Consolidation and Close.
B35: =IF('Scope Definition'!C36="YES","Audit will be enabled in the application as per requierement.", "")
B37: Application Customization
B38: =IF('Scope Definition'!C40="YES","Custom Data Forms – If required, up to " & 'Scope Definition'!D40 &" Custom Data Forms will be developed to support Financial Consolidation and Close.","") -> Custom Data Forms – If required, up to 5 Custom Data Forms will be developed to support Financial Consolidation and Close.
B40: =IF('Scope Definition'!C41="YES","Custom Dashboards – If required, up to " & 'Scope Definition'!D41 &" Custom Dashboards will be developed to support Financial Consolidation and Close.","")
B42: Calculations
B43: =IF('Scope Definition'!C44="YES","Custom Business Rules – If required, up to " & 'Scope Definition'!D44 &" Custom Business rules will be developed to support Financial Consolidation and Close.","") -> Custom Business Rules – If required, up to 3 Custom Business rules will be developed to support Financial Consolidation and Close.
B44: =IF('Scope Definition'!C45="YES","Member Formulas – If required, up to " & 'Scope Definition'!D45 &" Member Formulas will be developed to support Financial Consolidation and Close.","") -> Member Formulas – If required, up to 20 Member Formulas will be developed to support Financial Consolidation and Close.
B45: =IF('Scope Definition'!C46="YES","Translation override will be set up if required","") -> Translation override will be set up if required
B46: =IF('Scope Definition'!C47="YES","Calculate Movement rule will be enabled","")
B132: Key Design Decisions
B134: General Application Configuration | D134: General Application Configuration
B135: Metadata Configuration | D135: Metadata Configuration
B136: FCC Consolidations and Other Calculations | D136: FCC Consolidations and Other Calculations
B137: Reports and Data Form Configuration | D137: Reports and Data Form Configuration
...
